<mujoco model="inverted pendulum">
	<compiler inertiafromgeom="true"/>
	<default>
		<joint armature="0" damping="1" limited="true"/>
		<geom contype="0" friction="1 0.1 0.1" rgba="0.7 0.7 0 1"/>
	</default>
	<option gravity="0 0 -9.81" integrator="RK4" timestep="0.0001"/>
	<worldbody>
		<geom name="rail" pos="0 0 0" quat="0.707 0 0.707 0" rgba="0.3 0.3 0.7 1" size="0.02 3" type="capsule"/>
		<body name="cart" pos="0 0 0">
			<joint axis="1 0 0" limited="true" name="slider" pos="0 0 0" range="-3 3" type="slide"/>
			<geom name="cart" pos="0 0 0" quat="0.707 0 0.707 0" size="0.1 0.1" type="capsule"/>
			<body name="pole" pos="0 0 0">
				<joint axis="0 1 0" name="hinge" pos="0 0 0" range="-1800 1800" type="hinge"/>
				<geom name="pole" type="capsule" size="0.049 0.3" pos="0 0 0.3" axisangle="1 0 0 0" rgba="0 0.7 0.7 1"/>
			</body>
		</body>
	</worldbody>
	<actuator>
		<motor joint="slider" gear="1" name="slide"/>
	</actuator>
  <keyframe>
    <key name="up" 
      qpos="0 0.5"
      qvel="0 0"
    />
  </keyframe>
</mujoco>